<robot name="test_robot">
  <material name="red">
    <color rgba="1.0 0.0 0.0 1.0"/>
  </material>
  <material name="white">
    <color rgba="1.0 1.0 1.0 2.0"/>
  </material>
  <material name="yello">
    <color rgba="1.0 1.0 0.0 2.0"/>
  </material>
  <material name="black">
    <color rgba="0.0 0.0 0.0 1.0"/>
  </material>
  <material name="re">
    <color rgba="1.0 0.5 0.5 1.0"/>
  </material>

  <link name="base_link"/>

  <joint name="body1_joint" type="revolute">
    <parent link="base_link"/>
    <child  link="body1_link"/>
    <origin xyz="0 0 0" rpy="0 0 0"/>
    <limit lower="-2" upper="2" effort="0" velocity="0"/>
    <axis xyz="0 0 1"/>
  </joint>
  <link name="body1_link">
    <visual>
      <geometry>
        <box size="0.1 0.1 0.3"/>
      </geometry>
      <origin xyz="0 0 0.25" rpy="0 0 0"/>
      <material name="red"/>
    </visual>
  </link>

  <joint name="body2_joint" type="revolute">
    <parent link="body1_link"/>
    <child  link="body2_link"/>
    <origin xyz="0 0 0.3" rpy="0 0 0"/>
    <limit lower="-2" upper="2" effort="0" velocity="0"/>
  </joint>
  <link name="body2_link">
    <visual>
      <geometry>
        <box size="0.1 0.1 0.3"/>
      </geometry>
      <origin xyz="0 0 0.2" rpy="0 0 0"/>
      <material name="yello"/>
    </visual>
  </link>

  <joint name="body3_joint" type="revolute">
    <parent link="body2_link"/>
    <child  link="body3_link"/>
    <origin xyz="0 0 0.4" rpy="0 0 0"/>
    <limit lower="-2" upper="2" effort="0" velocity="0"/>
  </joint>
  <link name="body3_link">
    <visual>
      <geometry>
        <box size="0.1 0.1 0.5"/>
      </geometry>
      <origin xyz="0 0 0.2" rpy="0 0 0"/>
      <material name="black"/>
    </visual>
  </link>

   <joint name="body4_joint" type="revolute">
    <parent link="body3_link"/>
    <child  link="body4_link"/>
    <origin xyz="0.0 0 0.4" rpy="0 0 0"/>
    <limit lower="-2" upper="2" effort="0" velocity="0"/>
    <axis xyz="0 1 0"/>
  </joint>
  <link name="body4_link">
    <visual>
      <geometry>
        <box size="0.1 0.1 0.6"/>
      </geometry>
      <origin xyz="0 0 0.2" rpy="0 0 0"/>
      <material name="re"/>
    </visual>
  </link>
</robot>